Workbook

Sheet Plan de costos
A3: Costos RRHH | B3: Personal | C3: Pago x hora | D3: Aguinaldo | E3: Cantidad horas | F3: Total | H3: Item | I3: Total
A4: Scrum Master | B4: Felipe Araneda | C4: 10000 | D4: 70000 | E4: 160 | F4: =(E4*C4)+D4 -> 1670000 | H4: Costos RRHH | I4: =F4+F5+F6+F7+F8 -> 6580000
A5: Desarrollador 1 | B5: Elvis Olmedo | C5: 8000 | D5: 50000 | E5: 160 | F5: =E5*C5+D5 -> 1330000 | H5: Equipos e infraestructura | I5: =E12+E13+E14+E15 -> 4699930
A6: Desarrollador 2 | B6: Vicente Valdés | C6: 8000 | D6: 50000 | E6: 160 | F6: =E6*C6+D6 -> 1330000 | H6: Gastos generales e improvistos | I6: =D18+D19+D20+D21 -> 3820000
A7: Vendedor | B7: Juan Cabrera | C7: 6000 | D7: 40000 | E7: 160 | F7: =E7*C7+D7 -> 1000000 | H7: Gastos comunes | I7: =D24+D25+D26+D27 -> 450000
A8: QA | B8: Diego Lucero | C8: 7500 | D8: 50000 | E8: 160 | F8: =E8*C8+D8 -> 1250000 | I8: =I4+I5+I6+I7 -> 15549930
A11: Equipos e infraestructura | B11: Descripción | C11: Costo unitario o por mes | D11: Cantidad unidad o mes | E11: Total
A12: Notebooks | B12: Equipos para desarollar | C12: 649990 | D12: 2 | E12: =C12*D12 -> 1299980
A13: Perifericos | B13: Mouse | C13: 29990 | D13: 5 | E13: =C13*D13 -> 149950
A14: Sillas de escritorio | C14: 50000 | D14: 5 | E14: =C14*D14 -> 250000
A15: Oficina | B15: Lugar de desarrollo y reunion | C15: 750000 | D15: 4 | E15: =C15*D15 -> 3000000
A16: computador | B16: =B12 -> Equipos para desarollar | C16: =C15 -> 750000 | D16: 3 | E16: =C16*D16 -> 2250000
A17: Gastos generales e imprevistos | B17: Precio unitario | C17: Cantidad | D17: Total
A18: Transporte | B18: 1600 | C18: =140*5 -> 700 | D18: =C18*B18 -> 1120000
A19: Desayuno | B19: 2500 | C19: 100 | D19: =C19*B19 -> 250000 | F19: supuesto | G19: 20 dias habiles
A20: Almuerzo | B20: 4500 | C20: 100 | D20: =C20*B20 -> 450000
A21: Reserva de emergencia | B21: 2000000 | C21: 1 | D21: =C21*B21 -> 2000000
A23: Gastos comunes | B23: Precio unitario | C23: Cantidad de meses | D23: Total
A24: Agua | B24: 20000 | C24: 5 | D24: =C24*B24 -> 100000
A25: Luz | B25: 35000 | C25: 5 | D25: =C25*B25 -> 175000
A26: Gas | B26: 15000 | C26: 5 | D26: =C26*B26 -> 75000
A27: Internet | B27: 20000 | C27: 5 | D27: 100000

Sheet Flujo de caja
A1: Antedecentes | R1: Inversion | S1: =-B4 -> -34000000
A2: Presupuesto | B2: 35000000 | D2: EL PRESTAMO FUE SOLICITADO EL MES DE AGOSTO Y SE OPTO POR ELEGIR EL MES DE SEPTIEMPRE PARA EL NO PAGO POR LO QUE SE TERMINARÁ DE PAGAR EL CREDITO EN EL MES 14 | R2: Flujo 1 | S2: =B24 -> 31391082
A3: Costo del proyecto | B3: ='Plan de costos'!I8 -> 15549930 | R3: Flujo 2 | S3: =C24 -> 28594611
A4: Prestamo a solicitar | B4: 34000000 | R4: Flujo 3 | S4: =D24 -> 26352268
R5: Flujo 4 | S5: =E24 -> 20222443
R6: Flujo 5 | S6: =F24 -> 23349935
B7: Mes 1 | C7: Mes 2 | D7: Mes 3 | E7: Mes 4 | F7: Mes 5 | G7: Mes 6 | H7: Mes 7 | I7: Mes 8 | J7: Mes 9 | K7: Mes 10 | L7: Mes 11 | M7: Mes 12 | N7: Mes 13 | O7: Mes 14 | P7: Total | R7: Flujo 6 | S7: =G24 -> 20016580
A8: Egresos | R8: Flujo 7 | S8: =H24 -> 16683225
A9: Costos RRHH | B9: =B28*4 -> 1548235.3 | C9: =B28*4 -> 1548235.3 | D9: =B28*4 -> 1548235.3 | E9: =B28*4 -> 1548235.3 | F9: =B28 -> 387058.82 | G9: 0 | H9: 0 | I9: 0 | J9: 0 | K9: 0 | L9: 0 | M9: 0 | N9: 0 | O9: 0 | P9: =B9+C9+D9+E9+F9 -> 6580000 | R9: Flujo 8 | S9: =I24 -> 13349870
A10: Equipos e infraestructura | B10: ='Plan de costos'!E12+'Plan de costos'!E13+'Plan de costos'!E14+'Plan de costos'!C15 -> 2449930 | C10: ='Plan de costos'!C15 -> 750000 | D10: ='Plan de costos'!C15 -> 750000 | E10: ='Plan de costos'!C15 -> 750000 | F10: ='Plan de costos'!C15 -> 750000 | G10: 0 | H10: 0 | I10: 0 | J10: 0 | K10: 0 | L10: 0 | M10: 0 | N10: 0 | O10: 0 | P10: =SUM(B10:F10) -> 5449930 | R10: Flujo 9 | S10: =J24 -> 10016515
A11: Gastos generales e improvistos | B11: =(B30*4)+'Plan de costos'!D21 -> 2428235.3 | C11: =B30*4 -> 428235.29 | D11: =B30*4 -> 428235.29 | E11: =B30*4 -> 428235.29 | F11: =B30 -> 107058.82 | G11: 0 | H11: 0 | I11: 0 | J11: 0 | K11: 0 | L11: 0 | M11: 0 | N11: 0 | O11: 0 | P11: =SUM(B11:F11) -> 3820000 | R11: Flujo 10 | S11: =K24 -> 6683160
A12: Gastos comunes | B12: ='Plan de costos'!B26+'Plan de costos'!B25+'Plan de costos'!B24 -> 70000 | C12: ='Plan de costos'!B26+'Plan de costos'!B25+'Plan de costos'!B24 -> 70000 | D12: ='Plan de costos'!B26+'Plan de costos'!B25+'Plan de costos'!B24 -> 70000 | E12: ='Plan de costos'!B26+'Plan de costos'!B25+'Plan de costos'!B24 -> 70000 | F12: ='Plan de costos'!B26+'Plan de costos'!B25+'Plan de costos'!B24 -> 70000 | G12: 0 | H12: 0 | I12: 0 | J12: 0 | K12: 0 | L12: 0 | M12: 0 | N12: 0 | O12: 0 | P12: =SUM(B12:F12) -> 350000 | R12: Flujo 11 | S12: =L24 -> 3349805
A13: Pago credito | B13: 0 | C13: 0 | D13: 3333355 | E13: 3333355 | F13: 3333355 | G13: 3333355 | H13: 3333355 | I13: 3333355 | J13: 3333355 | K13: 3333355 | L13: 3333355 | M13: 3333355 | N13: 3333355 | O13: 3333355 | P13: =SUM(D13:O13) -> 40000260 | R13: Flujo 12 | S13: =M24 -> 16450
A14: Total egresos | B14: =SUM(B9:B13) -> 6496400.6 | C14: =SUM(C9:C13) -> 2796470.6 | D14: =SUM(D9:D13) -> 6129825.6 | E14: =SUM(E9:E13) -> 6129825.6 | F14: =SUM(F9:F13) -> 4647472.6 | G14: =SUM(G9:G13) -> 3333355 | H14: =SUM(H9:H13) -> 3333355 | I14: =SUM(I9:I13) -> 3333355 | ... O14: =SUM(O9:O13) -> 3333355 | R14: Flujo 13 | S14: =N24 -> -3316905
R15: Flujo 14 | S15: =O24 -> -6650260
A16: Se acordó con el cliente realizar el pago del proyecto en 3 cuotas, la primera el inicio del mismo de un 25%, la segunda en el tercer mes de 25%, y la ultima en la entrega del proyecto del 50%
A17: Ingresos
A18: Cuota 1 pago proyecto | B18: =B32 -> 3887482.5 | C18: =0 -> 0 | D18: =0 -> 0 | E18: =0 -> 0 | F18: =0 -> 0 | G18: =0 -> 0 | H18: =0 -> 0 | I18: =0 -> 0 | J18: =0 -> 0 | ... O18: =0 -> 0
A19: Cuota 2 pago proyecto | B19: =0 -> 0 | C19: =0 -> 0 | D19: =B32 -> 3887482.5 | E19: =0 -> 0 | F19: =0 -> 0 | G19: =0 -> 0 | H19: =0 -> 0 | I19: =0 -> 0 | J19: =0 -> 0 | K19: =0 -> 0 | L19: =0 -> 0 | ... O19: =0 -> 0 | R19: Tasa de descuento | S19: 0.5
A20: Cuota 3 pago proyecto | B20: =0 -> 0 | C20: =0 -> 0 | D20: =0 -> 0 | E20: =0 -> 0 | F20: =B33 -> 7774965 | G20: =0 -> 0 | H20: =0 -> 0 | I20: =0 -> 0 | J20: =0 -> 0 | K20: =0 -> 0 | L20: =0 -> 0 | M20: =0 -> 0 | N20: =0 -> 0 | O20: =0 -> 0
A21: Prestamo | B21: =B4 -> 34000000 | C21: =0 -> 0 | D21: =0 -> 0 | E21: =0 -> 0 | F21: =0 -> 0 | G21: =0 -> 0 | H21: =0 -> 0 | I21: =0 -> 0 | J21: =0 -> 0 | ... O21: =0 -> 0 | R21: TIR | S21: =IRR(S1:S6) -> 0.79843835
A22: Total ingresos | B22: =B18+B4 -> 37887482 | C22: =0 -> 0 | D22: =0 -> 0 | E22: =0 -> 0 | F22: =0 -> 0 | G22: =0 -> 0 | H22: =0 -> 0 | I22: =0 -> 0 | J22: =0 -> 0 | ... O22: =0 -> 0 | R22: VAN | S22: {=NPV(S19,S3:S6,S2)+S1} -> 11513166
A24: Flujo | B24: =B22-B14 -> 31391082 | C24: =B24-C14 -> 28594611 | D24: =C24+D19-D14 -> 26352268 | E24: =D24-E14 -> 20222443 | F24: =E24-F14+F20 -> 23349935 | G24: =F24-G14 -> 20016580 | H24: =G24-H14 -> 16683225 | I24: =H24-I14 -> 13349870 | J24: =I24-J14 -> 10016515 | K24: =J24-K14 -> 6683160 | L24: =K24-L14 -> 3349805 | M24: =L24-M14 -> 16450 | N24: =M24-N14 -> -3316905 | O24: =N24-O14 -> -6650260
A26: total semanas de trabajo | B26: ='Plan de costos'!E4 / 19 -> 8.4210526 | D26: =17/4 -> 4.25 | F26: EL PROYECTO FINALIZA EN EL MES 5 PERO EL CREDITO SE SEGUIRÁ PAGANDO HASTA EL MES 14, POR LO QUE HAY UN MARGEN DE 6 MESES PARA ENCONTRAR
A27: horas de trabajo por semana | B27: 19 | C27: =19*17 -> 323 | D27: =19/5 -> 3.8 | F27: UN NUEVO PROYECTO Y TERMINAR DE PAGAR EL PRIMER PRESTAMO
A28: costo RRHH por semana | B28: ='Plan de costos'!I4/17 -> 387058.82
A29: gastos equipos e infraestructura
A30: gastos generales e improvistos | B30: =C30/17 -> 107058.82 | C30: ='Plan de costos'!I6-'Plan de costos'!D21 -> 1820000
O31: Tasa de interés Anual: 21,72% | R31: 0.2172
A32: cuota 1 y 2 del proyecto | B32: =B3*0.25 -> 3887482.5
A33: cuota 3 | B33: =B32*2 -> 7774965
A37: Egresos | B37: Mes 1 | C37: Mes 2 | D37: Mes 3 | E37: Mes 4 | F37: Mes 5 | H37: Antedecentes | K37: Dashboard
A38: Costos RRHH | B38: =B9 -> 1548235.3 | C38: =C9 -> 1548235.3 | D38: =D9 -> 1548235.3 | E38: =E9 -> 1548235.3 | F38: =F9 -> 387058.82 | H38: Presupuesto | I38: =B2 -> 35000000 | K38: Inversion | L38: =S1 -> -34000000
A39: Equipos e infraestructura | B39: =B10 -> 2449930 | C39: =C10 -> 750000 | D39: =D10 -> 750000 | E39: =E10 -> 750000 | F39: =F10 -> 750000 | H39: Costo del proyecto | I39: =B3 -> 15549930 | K39: Flujo 1 | L39: =S2 -> 31391082
A40: Gastos generales e improvistos | B40: =B11 -> 2428235.3 | C40: =C11 -> 428235.29 | D40: =D11 -> 428235.29 | E40: =E11 -> 428235.29 | F40: =F11 -> 107058.82 | H40: Prestamo a solicitar | I40: =B4 -> 34000000 | K40: Flujo 2 | L40: =S3 -> 28594611
A41: Gastos comunes | B41: =B12 -> 70000 | C41: =C12 -> 70000 | D41: =D12 -> 70000 | E41: =E12 -> 70000 | F41: =F12 -> 70000 | K41: Flujo 3 | L41: =S4 -> 26352268
A42: Pago credito | B42: =B13 -> 0 | C42: =C13 -> 0 | D42: =D13 -> 3333355 | E42: =E13 -> 3333355 | F42: =F13 -> 3333355 | H42: Cuotas | I42: 14 | K42: Flujo 4 | L42: =S5 -> 20222443
A43: Total egresos | B43: =B14 -> 6496400.6 | C43: =C14 -> 2796470.6 | D43: =D14 -> 6129825.6 | E43: =E14 -> 6129825.6 | F43: =F14 -> 4647472.6 | H43: Costo total crédito | I43: =P13 -> 40000260 | K43: Flujo 5 | L43: =S6 -> 23349935
A44: Ingresos | H44: Valor Cuota | I44: =O13 -> 3333355 | K44: Tasa de descuento | L44: =S19 -> 0.5
A45: Cuota 1 pago proyecto | B45: =B18 -> 3887482.5 | C45: =C18 -> 0 | D45: =D18 -> 0 | E45: =E18 -> 0 | F45: =F18 -> 0 | H45: Interés | I45: =R31 -> 0.2172 | K45: TIR | L45: =S21 -> 0.79843835
...
